Workbook

Sheet Instructions
A1: DOKI recipe workbook
A2: One sheet per recipe. Row 3 of each sheet says what its weights are measured against.
A4: How to use
A5: Open the sheet for a recipe. In the shaded columns type the ingredient name and its weight. Everything to the right calculates itself: the percentage, the target, which scale should weigh it, and the tolerance that scale can actually hold.
A7: Two kinds of recipe
A8: Meat recipes (the jerky and the vinegar bath): weights are grams per 1 kg of meat. The station weighs the meat first and scales every ingredient to it.
A9: Fixed batches (Piri Piri Masala): weights are grams per batch — one standard size, no meat. The station skips the meat step and goes straight to recipe review with exactly these weights. Row 3 says 'Fixed batch'.
A11: Papain — the last step, by meat
A12: Papain is not on any recipe sheet. For the 7 jerky recipes, once every other ingredient is in, the station asks what the meat is: buffalo gets 6 g per kg of meat, chicken gets 2 g per kg of meat; anything else gets none. Change the rates in recipes.json.
A14: What the colours mean
A15: Shaded cells are yours to type in. Everything else is a formula — overwriting one breaks that row.
A16: A red row means neither scale can weigh that ingredient at this batch size. Split it, premix it, or make the batch bigger.
... A28: Run python3 xlsx_to_recipes.py DOKI-Recipes.xlsx to turn this workbook into the recipes.json the panel reads. It refuses to write a recipe that still has an unweighable ingredient or an untouched example row.

Sheet Settings
A1: Settings
A2: These drive every recipe sheet, and mirror recipes.json — the station reads that file, not this one.
A4: Tolerance (percent of target) | B4: 0.02 | C4: What the recipe asks for. The station uses this too.
A6: MAIN SCALE — name | B6: Main scale
A7: division (g) | B7: 1 | C7: Smallest step it reads. Copied from recipes.json — change it there.
A8: capacity (g) | B8: 50000
A9: usable (g) | B9: 50000 | C9: Capacity less the tub's tare.
A11: SMALL SCALE — name | B11: Small scale
A12: division (g) | B12: 0.1 | C12: SPEC NOT CONFIRMED — check the label on the scale.
A13: capacity (g) | B13: 3000 | C13: SPEC NOT CONFIRMED.
A14: usable (g) | B14: 2000 | C14: Capacity less the tare of the container you weigh into.
A17: Crossover — derived | B17: =2*Settings!$B$7/Settings!$B$4 -> 100 | C17: Below this the main scale cannot hold the tolerance: two of its divisions no longer fit inside the percentage.
A18: Crossover — override | B18: 4 | C18: Optional. Leave blank to use the derived value. A lower number keeps more ingredients on the main scale — easier to pour into, looser tolerance, and the recipe sheets say which.
A19: Crossover in force (g) | B19: =IF(B18="",B17,B18) -> 4
A21: Dead zone check | B21: =IF(Settings!$B$14>=Settings!$B$19,"None — the two scales meet","WARNING: nothing can weigh "&TEXT(Settings!$B$14,"#,##0")&" to "&TEXT(Settings!$B$19,"#,##0")&" g") -> None — the two scales meet

Sheet Vinegar Bath
A1: Vinegar Bath
A2: Type in the shaded cells only. Weights are GRAMS PER 1 KG OF MEAT. Everything to the right is calculated.
A3: Batch type | C3: Per 1 kg of meat | D3: Quantities scale with the meat weighed at the station.
A4: Batch base weight (g) | C4: 3200 | D4: A typical batch. Only the Target / Weigh-on / Tolerance columns use it — the station recomputes them from the meat it actually weighs.
A5: Product ID | C5: vinegar_bath | D5: Bases this applies to | F5: chicken, pork, beef, mutton, fish
A6: Flour ingredient | D6: Water ingredient
A7: Meat | D7: Which animal this product is made from. The operator is not asked — the product implies it. Leave blank if undecided.
A8: # | B8: Ingredient | C8: g per 1 kg meat | D8: % of meat | E8: Target in this batch | F8: Weigh on | G8: Tolerance ± | H8: Note
A9: =IF($B9="","",1) -> 1 | B9: White vinegar | C9: 15 | D9: =IF($B9="","",$C9/1000) -> 0.015 | E9: =IF($B9="","",$D9*$C$4) -> 48 | F9: =IF($B9="","",IF($C9=0,"Listed — not weighed",IF($E9<0,"NEITHER — negative weight",IF($E9>=Settings!$B$19,Settings!$B$6,IF($E9>Settings!$B$14,"NEITHER — over bench capacity",IF($E9>=2*Settings!$B$12,Settings!$B$11,"NEITHER — under bench resolution")))))) -> Main scale | G9: =IF($B9="","",IF($F9=Settings!$B$6,MAX(2*Settings!$B$7,Settings!$B$4*$E9),IF($F9=Settings!$B$11,MAX(2*Settings!$B$12,Settings!$B$4*$E9),""))) -> 2 | H9: =IF($B9="","",IF(LEFT($F9,6)="Listed","Quantity 0: shown on the station as a reminder, not weighed. Give it a weight to weigh it.",IF(LEFT($F9,7)="NEITHER","Cannot be weighed — split it, premix it, or raise the batch size",IF($G9>Settings!$B$4*$E9+0.0001,"Held to the scale's resolution, not "&TEXT(Settings!$B$4,"0%"),"")))) -> Held to the scale's resolution, not 2%
A10: =IF($B10="","",2) | D10: =IF($B10="","",$C10/1000) | E10: =IF($B10="","",$D10*$C$4) | F10: =IF($B10="","",IF($C10=0,"Listed — not weighed",IF($E10<0,"NEITHER — negative weight",IF($E10>=Settings!$B$19,Settings!$B$6,IF($E10>Settings!$B$14,"NEITHER — over bench capacity",IF($E10>=2*Settings!$B$12,Settings!$B$11,"NEITHER — under bench resolution")))))) | G10: =IF($B10="","",IF($F10=Settings!$B$6,MAX(2*Settings!$B$7,Settings!$B$4*$E10),IF($F10=Settings!$B$11,MAX(2*Settings!$B$12,Settings!$B$4*$E10),""))) | H10: =IF($B10="","",IF(LEFT($F10,6)="Listed","Quantity 0: shown on the station as a reminder, not weighed. Give it a weight to weigh it.",IF(LEFT($F10,7)="NEITHER","Cannot be weighed — split it, premix it, or raise the batch size",IF($G10>Settings!$B$4*$E10+0.0001,"Held to the scale's resolution, not "&TEXT(Settings!$B$4,"0%"),""))))
A11: =IF($B11="","",3) | D11: =IF($B11="","",$C11/1000) | E11: =IF($B11="","",$D11*$C$4) | F11: =IF($B11="","",IF($C11=0,"Listed — not weighed",IF($E11<0,"NEITHER — negative weight",IF($E11>=Settings!$B$19,Settings!$B$6,IF($E11>Settings!$B$14,"NEITHER — over bench capacity",IF($E11>=2*Settings!$B$12,Settings!$B$11,"NEITHER — under bench resolution")))))) | G11: =IF($B11="","",IF($F11=Settings!$B$6,MAX(2*Settings!$B$7,Settings!$B$4*$E11),IF($F11=Settings!$B$11,MAX(2*Settings!$B$12,Settings!$B$4*$E11),""))) | H11: =IF($B11="","",IF(LEFT($F11,6)="Listed","Quantity 0: shown on the station as a reminder, not weighed. Give it a weight to weigh it.",IF(LEFT($F11,7)="NEITHER","Cannot be weighed — split it, premix it, or raise the batch size",IF($G11>Settings!$B$4*$E11+0.0001,"Held to the scale's resolution, not "&TEXT(Settings!$B$4,"0%"),""))))
A12: =IF($B12="","",4) | D12: =IF($B12="","",$C12/1000) | E12: =IF($B12="","",$D12*$C$4) | F12: =IF($B12="","",IF($C12=0,"Listed — not weighed",IF($E12<0,"NEITHER — negative weight",IF($E12>=Settings!$B$19,Settings!$B$6,IF($E12>Settings!$B$14,"NEITHER — over bench capacity",IF($E12>=2*Settings!$B$12,Settings!$B$11,"NEITHER — under bench resolution")))))) | G12: =IF($B12="","",IF($F12=Settings!$B$6,MAX(2*Settings!$B$7,Settings!$B$4*$E12),IF($F12=Settings!$B$11,MAX(2*Settings!$B$12,Settings!$B$4*$E12),""))) | H12: =IF($B12="","",IF(LEFT($F12,6)="Listed","Quantity 0: shown on the station as a reminder, not weighed. Give it a weight to weigh it.",IF(LEFT($F12,7)="NEITHER","Cannot be weighed — split it, premix it, or raise the batch size",IF($G12>Settings!$B$4*$E12+0.0001,"Held to the scale's resolution, not "&TEXT(Settings!$B$4,"0%"),""))))
A13: =IF($B13="","",5) | D13: =IF($B13="","",$C13/1000) | E13: =IF($B13="","",$D13*$C$4) | F13: =IF($B13="","",IF($C13=0,"Listed — not weighed",IF($E13<0,"NEITHER — negative weight",IF($E13>=Settings!$B$19,Settings!$B$6,IF($E13>Settings!$B$14,"NEITHER — over bench capacity",IF($E13>=2*Settings!$B$12,Settings!$B$11,"NEITHER — under bench resolution")))))) | G13: =IF($B13="","",IF($F13=Settings!$B$6,MAX(2*Settings!$B$7,Settings!$B$4*$E13),IF($F13=Settings!$B$11,MAX(2*Settings!$B$12,Settings!$B$4*$E13),""))) | H13: =IF($B13="","",IF(LEFT($F13,6)="Listed","Quantity 0: shown on the station as a reminder, not weighed. Give it a weight to weigh it.",IF(LEFT($F13,7)="NEITHER","Cannot be weighed — split it, premix it, or raise the batch size",IF($G13>Settings!$B$4*$E13+0.0001,"Held to the scale's resolution, not "&TEXT(Settings!$B$4,"0%"),""))))
A14: =IF($B14="","",6) | D14: =IF($B14="","",$C14/1000) | E14: =IF($B14="","",$D14*$C$4) | F14: =IF($B14="","",IF($C14=0,"Listed — not weighed",IF($E14<0,"NEITHER — negative weight",IF($E14>=Settings!$B$19,Settings!$B$6,IF($E14>Settings!$B$14,"NEITHER — over bench capacity",IF($E14>=2*Settings!$B$12,Settings!$B$11,"NEITHER — under bench resolution")))))) | G14: =IF($B14="","",IF($F14=Settings!$B$6,MAX(2*Settings!$B$7,Settings!$B$4*$E14),IF($F14=Settings!$B$11,MAX(2*Settings!$B$12,Settings!$B$4*$E14),""))) | H14: =IF($B14="","",IF(LEFT($F14,6)="Listed","Quantity 0: shown on the station as a reminder, not weighed. Give it a weight to weigh it.",IF(LEFT($F14,7)="NEITHER","Cannot be weighed — split it, premix it, or raise the batch size",IF($G14>Settings!$B$4*$E14+0.0001,"Held to the scale's resolution, not "&TEXT(Settings!$B$4,"0%"),""))))
A15: =IF($B15="","",7) | D15: =IF($B15="","",$C15/1000) | E15: =IF($B15="","",$D15*$C$4) | F15: =IF($B15="","",IF($C15=0,"Listed — not weighed",IF($E15<0,"NEITHER — negative weight",IF($E15>=Settings!$B$19,Settings!$B$6,IF($E15>Settings!$B$14,"NEITHER — over bench capacity",IF($E15>=2*Settings!$B$12,Settings!$B$11,"NEITHER — under bench resolution")))))) | G15: =IF($B15="","",IF($F15=Settings!$B$6,MAX(2*Settings!$B$7,Settings!$B$4*$E15),IF($F15=Settings!$B$11,MAX(2*Settings!$B$12,Settings!$B$4*$E15),""))) | H15: =IF($B15="","",IF(LEFT($F15,6)="Listed","Quantity 0: shown on the station as a reminder, not weighed. Give it a weight to weigh it.",IF(LEFT($F15,7)="NEITHER","Cannot be weighed — split it, premix it, or raise the batch size",IF($G15>Settings!$B$4*$E15+0.0001,"Held to the scale's resolution, not "&TEXT(Settings!$B$4,"0%"),""))))
A16: =IF($B16="","",8) | D16: =IF($B16="","",$C16/1000) | E16: =IF($B16="","",$D16*$C$4) | F16: =IF($B16="","",IF($C16=0,"Listed — not weighed",IF($E16<0,"NEITHER — negative weight",IF($E16>=Settings!$B$19,Settings!$B$6,IF($E16>Settings!$B$14,"NEITHER — over bench capacity",IF($E16>=2*Settings!$B$12,Settings!$B$11,"NEITHER — under bench resolution")))))) | G16: =IF($B16="","",IF($F16=Settings!$B$6,MAX(2*Settings!$B$7,Settings!$B$4*$E16),IF($F16=Settings!$B$11,MAX(2*Settings!$B$12,Settings!$B$4*$E16),""))) | H16: =IF($B16="","",IF(LEFT($F16,6)="Listed","Quantity 0: shown on the station as a reminder, not weighed. Give it a weight to weigh it.",IF(LEFT($F16,7)="NEITHER","Cannot be weighed — split it, premix it, or raise the batch size",IF($G16>Settings!$B$4*$E16+0.0001,"Held to the scale's resolution, not "&TEXT(Settings!$B$4,"0%"),""))))
A17: =IF($B17="","",9) | D17: =IF($B17="","",$C17/1000) | E17: =IF($B17="","",$D17*$C$4) | F17: =IF($B17="","",IF($C17=0,"Listed — not weighed",IF($E17<0,"NEITHER — negative weight",IF($E17>=Settings!$B$19,Settings!$B$6,IF($E17>Settings!$B$14,"NEITHER — over bench capacity",IF($E17>=2*Settings!$B$12,Settings!$B$11,"NEITHER — under bench resolution")))))) | G17: =IF($B17="","",IF($F17=Settings!$B$6,MAX(2*Settings!$B$7,Settings!$B$4*$E17),IF($F17=Settings!$B$11,MAX(2*Settings!$B$12,Settings!$B$4*$E17),""))) | H17: =IF($B17="","",IF(LEFT($F17,6)="Listed","Quantity 0: shown on the station as a reminder, not weighed. Give it a weight to weigh it.",IF(LEFT($F17,7)="NEITHER","Cannot be weighed — split it, premix it, or raise the batch size",IF($G17>Settings!$B$4*$E17+0.0001,"Held to the scale's resolution, not "&TEXT(Settings!$B$4,"0%"),""))))
A18: =IF($B18="","",10) | D18: =IF($B18="","",$C18/1000) | E18: =IF($B18="","",$D18*$C$4) | F18: =IF($B18="","",IF($C18=0,"Listed — not weighed",IF($E18<0,"NEITHER — negative weight",IF($E18>=Settings!$B$19,Settings!$B$6,IF($E18>Settings!$B$14,"NEITHER — over bench capacity",IF($E18>=2*Settings!$B$12,Settings!$B$11,"NEITHER — under bench resolution")))))) | G18: =IF($B18="","",IF($F18=Settings!$B$6,MAX(2*Settings!$B$7,Settings!$B$4*$E18),IF($F18=Settings!$B$11,MAX(2*Settings!$B$12,Settings!$B$4*$E18),""))) | H18: =IF($B18="","",IF(LEFT($F18,6)="Listed","Quantity 0: shown on the station as a reminder, not weighed. Give it a weight to weigh it.",IF(LEFT($F18,7)="NEITHER","Cannot be weighed — split it, premix it, or raise the batch size",IF($G18>Settings!$B$4*$E18+0.0001,"Held to the scale's resolution, not "&TEXT(Settings!$B$4,"0%"),""))))
A19: =IF($B19="","",11) | D19: =IF($B19="","",$C19/1000) | E19: =IF($B19="","",$D19*$C$4) | F19: =IF($B19="","",IF($C19=0,"Listed — not weighed",IF($E19<0,"NEITHER — negative weight",IF($E19>=Settings!$B$19,Settings!$B$6,IF($E19>Settings!$B$14,"NEITHER — over bench capacity",IF($E19>=2*Settings!$B$12,Settings!$B$11,"NEITHER — under bench resolution")))))) | G19: =IF($B19="","",IF($F19=Settings!$B$6,MAX(2*Settings!$B$7,Settings!$B$4*$E19),IF($F19=Settings!$B$11,MAX(2*Settings!$B$12,Settings!$B$4*$E19),""))) | H19: =IF($B19="","",IF(LEFT($F19,6)="Listed","Quantity 0: shown on the station as a reminder, not weighed. Give it a weight to weigh it.",IF(LEFT($F19,7)="NEITHER","Cannot be weighed — split it, premix it, or raise the batch size",IF($G19>Settings!$B$4*$E19+0.0001,"Held to the scale's resolution, not "&TEXT(Settings!$B$4,"0%"),""))))
A20: =IF($B20="","",12) | D20: =IF($B20="","",$C20/1000) | E20: =IF($B20="","",$D20*$C$4) | F20: =IF($B20="","",IF($C20=0,"Listed — not weighed",IF($E20<0,"NEITHER — negative weight",IF($E20>=Settings!$B$19,Settings!$B$6,IF($E20>Settings!$B$14,"NEITHER — over bench capacity",IF($E20>=2*Settings!$B$12,Settings!$B$11,"NEITHER — under bench resolution")))))) | G20: =IF($B20="","",IF($F20=Settings!$B$6,MAX(2*Settings!$B$7,Settings!$B$4*$E20),IF($F20=Settings!$B$11,MAX(2*Settings!$B$12,Settings!$B$4*$E20),""))) | H20: =IF($B20="","",IF(LEFT($F20,6)="Listed","Quantity 0: shown on the station as a reminder, not weighed. Give it a weight to weigh it.",IF(LEFT($F20,7)="NEITHER","Cannot be weighed — split it, premix it, or raise the batch size",IF($G20>Settings!$B$4*$E20+0.0001,"Held to the scale's resolution, not "&TEXT(Settings!$B$4,"0%"),""))))
A21: =IF($B21="","",13) | D21: =IF($B21="","",$C21/1000) | E21: =IF($B21="","",$D21*$C$4) | F21: =IF($B21="","",IF($C21=0,"Listed — not weighed",IF($E21<0,"NEITHER — negative weight",IF($E21>=Settings!$B$19,Settings!$B$6,IF($E21>Settings!$B$14,"NEITHER — over bench capacity",IF($E21>=2*Settings!$B$12,Settings!$B$11,"NEITHER — under bench resolution")))))) | G21: =IF($B21="","",IF($F21=Settings!$B$6,MAX(2*Settings!$B$7,Settings!$B$4*$E21),IF($F21=Settings!$B$11,MAX(2*Settings!$B$12,Settings!$B$4*$E21),""))) | H21: =IF($B21="","",IF(LEFT($F21,6)="Listed","Quantity 0: shown on the station as a reminder, not weighed. Give it a weight to weigh it.",IF(LEFT($F21,7)="NEITHER","Cannot be weighed — split it, premix it, or raise the batch size",IF($G21>Settings!$B$4*$E21+0.0001,"Held to the scale's resolution, not "&TEXT(Settings!$B$4,"0%"),""))))
A22: =IF($B22="","",14) | D22: =IF($B22="","",$C22/1000) | E22: =IF($B22="","",$D22*$C$4) | F22: =IF($B22="","",IF($C22=0,"Listed — not weighed",IF($E22<0,"NEITHER — negative weight",IF($E22>=Settings!$B$19,Settings!$B$6,IF($E22>Settings!$B$14,"NEITHER — over bench capacity",IF($E22>=2*Settings!$B$12,Settings!$B$11,"NEITHER — under bench resolution")))))) | G22: =IF($B22="","",IF($F22=Settings!$B$6,MAX(2*Settings!$B$7,Settings!$B$4*$E22),IF($F22=Settings!$B$11,MAX(2*Settings!$B$12,Settings!$B$4*$E22),""))) | H22: =IF($B22="","",IF(LEFT($F22,6)="Listed","Quantity 0: shown on the station as a reminder, not weighed. Give it a weight to weigh it.",IF(LEFT($F22,7)="NEITHER","Cannot be weighed — split it, premix it, or raise the batch size",IF($G22>Settings!$B$4*$E22+0.0001,"Held to the scale's resolution, not "&TEXT(Settings!$B$4,"0%"),""))))
A23: =IF($B23="","",15) | D23: =IF($B23="","",$C23/1000) | E23: =IF($B23="","",$D23*$C$4) | F23: =IF($B23="","",IF($C23=0,"Listed — not weighed",IF($E23<0,"NEITHER — negative weight",IF($E23>=Settings!$B$19,Settings!$B$6,IF($E23>Settings!$B$14,"NEITHER — over bench capacity",IF($E23>=2*Settings!$B$12,Settings!$B$11,"NEITHER — under bench resolution")))))) | G23: =IF($B23="","",IF($F23=Settings!$B$6,MAX(2*Settings!$B$7,Settings!$B$4*$E23),IF($F23=Settings!$B$11,MAX(2*Settings!$B$12,Settings!$B$4*$E23),""))) | H23: =IF($B23="","",IF(LEFT($F23,6)="Listed","Quantity 0: shown on the station as a reminder, not weighed. Give it a weight to weigh it.",IF(LEFT($F23,7)="NEITHER","Cannot be weighed — split it, premix it, or raise the batch size",IF($G23>Settings!$B$4*$E23+0.0001,"Held to the scale's resolution, not "&TEXT(Settings!$B$4,"0%"),""))))
A24: =IF($B24="","",16) | D24: =IF($B24="","",$C24/1000) | E24: =IF($B24="","",$D24*$C$4) | F24: =IF($B24="","",IF($C24=0,"Listed — not weighed",IF($E24<0,"NEITHER — negative weight",IF($E24>=Settings!$B$19,Settings!$B$6,IF($E24>Settings!$B$14,"NEITHER — over bench capacity",IF($E24>=2*Settings!$B$12,Settings!$B$11,"NEITHER — under bench resolution")))))) | G24: =IF($B24="","",IF($F24=Settings!$B$6,MAX(2*Settings!$B$7,Settings!$B$4*$E24),IF($F24=Settings!$B$11,MAX(2*Settings!$B$12,Settings!$B$4*$E24),""))) | H24: =IF($B24="","",IF(LEFT($F24,6)="Listed","Quantity 0: shown on the station as a reminder, not weighed. Give it a weight to weigh it.",IF(LEFT($F24,7)="NEITHER","Cannot be weighed — split it, premix it, or raise the batch size",IF($G24>Settings!$B$4*$E24+0.0001,"Held to the scale's resolution, not "&TEXT(Settings!$B$4,"0%"),""))))
A25: =IF($B25="","",17) | D25: =IF($B25="","",$C25/1000) | E25: =IF($B25="","",$D25*$C$4) | F25: =IF($B25="","",IF($C25=0,"Listed — not weighed",IF($E25<0,"NEITHER — negative weight",IF($E25>=Settings!$B$19,Settings!$B$6,IF($E25>Settings!$B$14,"NEITHER — over bench capacity",IF($E25>=2*Settings!$B$12,Settings!$B$11,"NEITHER — under bench resolution")))))) | G25: =IF($B25="","",IF($F25=Settings!$B$6,MAX(2*Settings!$B$7,Settings!$B$4*$E25),IF($F25=Settings!$B$11,MAX(2*Settings!$B$12,Settings!$B$4*$E25),""))) | H25: =IF($B25="","",IF(LEFT($F25,6)="Listed","Quantity 0: shown on the station as a reminder, not weighed. Give it a weight to weigh it.",IF(LEFT($F25,7)="NEITHER","Cannot be weighed — split it, premix it, or raise the batch size",IF($G25>Settings!$B$4*$E25+0.0001,"Held to the scale's resolution, not "&TEXT(Settings!$B$4,"0%"),""))))
A26: =IF($B26="","",18) | D26: =IF($B26="","",$C26/1000) | E26: =IF($B26="","",$D26*$C$4) | F26: =IF($B26="","",IF($C26=0,"Listed — not weighed",IF($E26<0,"NEITHER — negative weight",IF($E26>=Settings!$B$19,Settings!$B$6,IF($E26>Settings!$B$14,"NEITHER — over bench capacity",IF($E26>=2*Settings!$B$12,Settings!$B$11,"NEITHER — under bench resolution")))))) | G26: =IF($B26="","",IF($F26=Settings!$B$6,MAX(2*Settings!$B$7,Settings!$B$4*$E26),IF($F26=Settings!$B$11,MAX(2*Settings!$B$12,Settings!$B$4*$E26),""))) | H26: =IF($B26="","",IF(LEFT($F26,6)="Listed","Quantity 0: shown on the station as a reminder, not weighed. Give it a weight to weigh it.",IF(LEFT($F26,7)="NEITHER","Cannot be weighed — split it, premix it, or raise the batch size",IF($G26>Settings!$B$4*$E26+0.0001,"Held to the scale's resolution, not "&TEXT(Settings!$B$4,"0%"),""))))
A27: =IF($B27="","",19) | D27: =IF($B27="","",$C27/1000) | E27: =IF($B27="","",$D27*$C$4) | F27: =IF($B27="","",IF($C27=0,"Listed — not weighed",IF($E27<0,"NEITHER — negative weight",IF($E27>=Settings!$B$19,Settings!$B$6,IF($E27>Settings!$B$14,"NEITHER — over bench capacity",IF($E27>=2*Settings!$B$12,Settings!$B$11,"NEITHER — under bench resolution")))))) | G27: =IF($B27="","",IF($F27=Settings!$B$6,MAX(2*Settings!$B$7,Settings!$B$4*$E27),IF($F27=Settings!$B$11,MAX(2*Settings!$B$12,Settings!$B$4*$E27),""))) | H27: =IF($B27="","",IF(LEFT($F27,6)="Listed","Quantity 0: shown on the station as a reminder, not weighed. Give it a weight to weigh it.",IF(LEFT($F27,7)="NEITHER","Cannot be weighed — split it, premix it, or raise the batch size",IF($G27>Settings!$B$4*$E27+0.0001,"Held to the scale's resolution, not "&TEXT(Settings!$B$4,"0%"),""))))
A28: =IF($B28="","",20) | D28: =IF($B28="","",$C28/1000) | E28: =IF($B28="","",$D28*$C$4) | F28: =IF($B28="","",IF($C28=0,"Listed — not weighed",IF($E28<0,"NEITHER — negative weight",IF($E28>=Settings!$B$19,Settings!$B$6,IF($E28>Settings!$B$14,"NEITHER — over bench capacity",IF($E28>=2*Settings!$B$12,Settings!$B$11,"NEITHER — under bench resolution")))))) | G28: =IF($B28="","",IF($F28=Settings!$B$6,MAX(2*Settings!$B$7,Settings!$B$4*$E28),IF($F28=Settings!$B$11,MAX(2*Settings!$B$12,Settings!$B$4*$E28),""))) | H28: =IF($B28="","",IF(LEFT($F28,6)="Listed","Quantity 0: shown on the station as a reminder, not weighed. Give it a weight to weigh it.",IF(LEFT($F28,7)="NEITHER","Cannot be weighed — split it, premix it, or raise the batch size",IF($G28>Settings!$B$4*$E28+0.0001,"Held to the scale's resolution, not "&TEXT(Settings!$B$4,"0%"),""))))
A29: =IF($B29="","",21) | D29: =IF($B29="","",$C29/1000) | E29: =IF($B29="","",$D29*$C$4) | F29: =IF($B29="","",IF($C29=0,"Listed — not weighed",IF($E29<0,"NEITHER — negative weight",IF($E29>=Settings!$B$19,Settings!$B$6,IF($E29>Settings!$B$14,"NEITHER — over bench capacity",IF($E29>=2*Settings!$B$12,Settings!$B$11,"NEITHER — under bench resolution")))))) | G29: =IF($B29="","",IF($F29=Settings!$B$6,MAX(2*Settings!$B$7,Settings!$B$4*$E29),IF($F29=Settings!$B$11,MAX(2*Settings!$B$12,Settings!$B$4*$E29),""))) | H29: =IF($B29="","",IF(LEFT($F29,6)="Listed","Quantity 0: shown on the station as a reminder, not weighed. Give it a weight to weigh it.",IF(LEFT($F29,7)="NEITHER","Cannot be weighed — split it, premix it, or raise the batch size",IF($G29>Settings!$B$4*$E29+0.0001,"Held to the scale's resolution, not "&TEXT(Settings!$B$4,"0%"),""))))
A30: =IF($B30="","",22) | D30: =IF($B30="","",$C30/1000) | E30: =IF($B30="","",$D30*$C$4) | F30: =IF($B30="","",IF($C30=0,"Listed — not weighed",IF($E30<0,"NEITHER — negative weight",IF($E30>=Settings!$B$19,Settings!$B$6,IF($E30>Settings!$B$14,"NEITHER — over bench capacity",IF($E30>=2*Settings!$B$12,Settings!$B$11,"NEITHER — under bench resolution")))))) | G30: =IF($B30="","",IF($F30=Settings!$B$6,MAX(2*Settings!$B$7,Settings!$B$4*$E30),IF($F30=Settings!$B$11,MAX(2*Settings!$B$12,Settings!$B$4*$E30),""))) | H30: =IF($B30="","",IF(LEFT($F30,6)="Listed","Quantity 0: shown on the station as a reminder, not weighed. Give it a weight to weigh it.",IF(LEFT($F30,7)="NEITHER","Cannot be weighed — split it, premix it, or raise the batch size",IF($G30>Settings!$B$4*$E30+0.0001,"Held to the scale's resolution, not "&TEXT(Settings!$B$4,"0%"),""))))
A31: =IF($B31="","",23) | D31: =IF($B31="","",$C31/1000) | E31: =IF($B31="","",$D31*$C$4) | F31: =IF($B31="","",IF($C31=0,"Listed — not weighed",IF($E31<0,"NEITHER — negative weight",IF($E31>=Settings!$B$19,Settings!$B$6,IF($E31>Settings!$B$14,"NEITHER — over bench capacity",IF($E31>=2*Settings!$B$12,Settings!$B$11,"NEITHER — under bench resolution")))))) | G31: =IF($B31="","",IF($F31=Settings!$B$6,MAX(2*Settings!$B$7,Settings!$B$4*$E31),IF($F31=Settings!$B$11,MAX(2*Settings!$B$12,Settings!$B$4*$E31),""))) | H31: =IF($B31="","",IF(LEFT($F31,6)="Listed","Quantity 0: shown on the station as a reminder, not weighed. Give it a weight to weigh it.",IF(LEFT($F31,7)="NEITHER","Cannot be weighed — split it, premix it, or raise the batch size",IF($G31>Settings!$B$4*$E31+0.0001,"Held to the scale's resolution, not "&TEXT(Settings!$B$4,"0%"),""))))
A32: =IF($B32="","",24) | D32: =IF($B32="","",$C32/1000) | E32: =IF($B32="","",$D32*$C$4) | F32: =IF($B32="","",IF($C32=0,"Listed — not weighed",IF($E32<0,"NEITHER — negative weight",IF($E32>=Settings!$B$19,Settings!$B$6,IF($E32>Settings!$B$14,"NEITHER — over bench capacity",IF($E32>=2*Settings!$B$12,Settings!$B$11,"NEITHER — under bench resolution")))))) | G32: =IF($B32="","",IF($F32=Settings!$B$6,MAX(2*Settings!$B$7,Settings!$B$4*$E32),IF($F32=Settings!$B$11,MAX(2*Settings!$B$12,Settings!$B$4*$E32),""))) | H32: =IF($B32="","",IF(LEFT($F32,6)="Listed","Quantity 0: shown on the station as a reminder, not weighed. Give it a weight to weigh it.",IF(LEFT($F32,7)="NEITHER","Cannot be weighed — split it, premix it, or raise the batch size",IF($G32>Settings!$B$4*$E32+0.0001,"Held to the scale's resolution, not "&TEXT(Settings!$B$4,"0%"),""))))
A33: =IF($B33="","",25) | D33: =IF($B33="","",$C33/1000) | E33: =IF($B33="","",$D33*$C$4) | F33: =IF($B33="","",IF($C33=0,"Listed — not weighed",IF($E33<0,"NEITHER — negative weight",IF($E33>=Settings!$B$19,Settings!$B$6,IF($E33>Settings!$B$14,"NEITHER — over bench capacity",IF($E33>=2*Settings!$B$12,Settings!$B$11,"NEITHER — under bench resolution")))))) | G33: =IF($B33="","",IF($F33=Settings!$B$6,MAX(2*Settings!$B$7,Settings!$B$4*$E33),IF($F33=Settings!$B$11,MAX(2*Settings!$B$12,Settings!$B$4*$E33),""))) | H33: =IF($B33="","",IF(LEFT($F33,6)="Listed","Quantity 0: shown on the station as a reminder, not weighed. Give it a weight to weigh it.",IF(LEFT($F33,7)="NEITHER","Cannot be weighed — split it, premix it, or raise the batch size",IF($G33>Settings!$B$4*$E33+0.0001,"Held to the scale's resolution, not "&TEXT(Settings!$B$4,"0%"),""))))
A34: =IF($B34="","",26) | D34: =IF($B34="","",$C34/1000) | E34: =IF($B34="","",$D34*$C$4) | F34: =IF($B34="","",IF($C34=0,"Listed — not weighed",IF($E34<0,"NEITHER — negative weight",IF($E34>=Settings!$B$19,Settings!$B$6,IF($E34>Settings!$B$14,"NEITHER — over bench capacity",IF($E34>=2*Settings!$B$12,Settings!$B$11,"NEITHER — under bench resolution")))))) | G34: =IF($B34="","",IF($F34=Settings!$B$6,MAX(2*Settings!$B$7,Settings!$B$4*$E34),IF($F34=Settings!$B$11,MAX(2*Settings!$B$12,Settings!$B$4*$E34),""))) | H34: =IF($B34="","",IF(LEFT($F34,6)="Listed","Quantity 0: shown on the station as a reminder, not weighed. Give it a weight to weigh it.",IF(LEFT($F34,7)="NEITHER","Cannot be weighed — split it, premix it, or raise the batch size",IF($G34>Settings!$B$4*$E34+0.0001,"Held to the scale's resolution, not "&TEXT(Settings!$B$4,"0%"),""))))
A35: =IF($B35="","",27) | D35: =IF($B35="","",$C35/1000) | E35: =IF($B35="","",$D35*$C$4) | F35: =IF($B35="","",IF($C35=0,"Listed — not weighed",IF($E35<0,"NEITHER — negative weight",IF($E35>=Settings!$B$19,Settings!$B$6,IF($E35>Settings!$B$14,"NEITHER — over bench capacity",IF($E35>=2*Settings!$B$12,Settings!$B$11,"NEITHER — under bench resolution")))))) | G35: =IF($B35="","",IF($F35=Settings!$B$6,MAX(2*Settings!$B$7,Settings!$B$4*$E35),IF($F35=Settings!$B$11,MAX(2*Settings!$B$12,Settings!$B$4*$E35),""))) | H35: =IF($B35="","",IF(LEFT($F35,6)="Listed","Quantity 0: shown on the station as a reminder, not weighed. Give it a weight to weigh it.",IF(LEFT($F35,7)="NEITHER","Cannot be weighed — split it, premix it, or raise the batch size",IF($G35>Settings!$B$4*$E35+0.0001,"Held to the scale's resolution, not "&TEXT(Settings!$B$4,"0%"),""))))
A36: =IF($B36="","",28) | D36: =IF($B36="","",$C36/1000) | E36: =IF($B36="","",$D36*$C$4) | F36: =IF($B36="","",IF($C36=0,"Listed — not weighed",IF($E36<0,"NEITHER — negative weight",IF($E36>=Settings!$B$19,Settings!$B$6,IF($E36>Settings!$B$14,"NEITHER — over bench capacity",IF($E36>=2*Settings!$B$12,Settings!$B$11,"NEITHER — under bench resolution")))))) | G36: =IF($B36="","",IF($F36=Settings!$B$6,MAX(2*Settings!$B$7,Settings!$B$4*$E36),IF($F36=Settings!$B$11,MAX(2*Settings!$B$12,Settings!$B$4*$E36),""))) | H36: =IF($B36="","",IF(LEFT($F36,6)="Listed","Quantity 0: shown on the station as a reminder, not weighed. Give it a weight to weigh it.",IF(LEFT($F36,7)="NEITHER","Cannot be weighed — split it, premix it, or raise the batch size",IF($G36>Settings!$B$4*$E36+0.0001,"Held to the scale's resolution, not "&TEXT(Settings!$B$4,"0%"),""))))
A37: =IF($B37="","",29) | D37: =IF($B37="","",$C37/1000) | E37: =IF($B37="","",$D37*$C$4) | F37: =IF($B37="","",IF($C37=0,"Listed — not weighed",IF($E37<0,"NEITHER — negative weight",IF($E37>=Settings!$B$19,Settings!$B$6,IF($E37>Settings!$B$14,"NEITHER — over bench capacity",IF($E37>=2*Settings!$B$12,Settings!$B$11,"NEITHER — under bench resolution")))))) | G37: =IF($B37="","",IF($F37=Settings!$B$6,MAX(2*Settings!$B$7,Settings!$B$4*$E37),IF($F37=Settings!$B$11,MAX(2*Settings!$B$12,Settings!$B$4*$E37),""))) | H37: =IF($B37="","",IF(LEFT($F37,6)="Listed","Quantity 0: shown on the station as a reminder, not weighed. Give it a weight to weigh it.",IF(LEFT($F37,7)="NEITHER","Cannot be weighed — split it, premix it, or raise the batch size",IF($G37>Settings!$B$4*$E37+0.0001,"Held to the scale's resolution, not "&TEXT(Settings!$B$4,"0%"),""))))
A38: =IF($B38="","",30) | D38: =IF($B38="","",$C38/1000) | E38: =IF($B38="","",$D38*$C$4) | F38: =IF($B38="","",IF($C38=0,"Listed — not weighed",IF($E38<0,"NEITHER — negative weight",IF($E38>=Settings!$B$19,Settings!$B$6,IF($E38>Settings!$B$14,"NEITHER — over bench capacity",IF($E38>=2*Settings!$B$12,Settings!$B$11,"NEITHER — under bench resolution")))))) | G38: =IF($B38="","",IF($F38=Settings!$B$6,MAX(2*Settings!$B$7,Settings!$B$4*$E38),IF($F38=Settings!$B$11,MAX(2*Settings!$B$12,Settings!$B$4*$E38),""))) | H38: =IF($B38="","",IF(LEFT($F38,6)="Listed","Quantity 0: shown on the station as a reminder, not weighed. Give it a weight to weigh it.",IF(LEFT($F38,7)="NEITHER","Cannot be weighed — split it, premix it, or raise the batch size",IF($G38>Settings!$B$4*$E38+0.0001,"Held to the scale's resolution, not "&TEXT(Settings!$B$4,"0%"),""))))
A39: =IF($B39="","",31) | D39: =IF($B39="","",$C39/1000) | E39: =IF($B39="","",$D39*$C$4) | F39: =IF($B39="","",IF($C39=0,"Listed — not weighed",IF($E39<0,"NEITHER — negative weight",IF($E39>=Settings!$B$19,Settings!$B$6,IF($E39>Settings!$B$14,"NEITHER — over bench capacity",IF($E39>=2*Settings!$B$12,Settings!$B$11,"NEITHER — under bench resolution")))))) | G39: =IF($B39="","",IF($F39=Settings!$B$6,MAX(2*Settings!$B$7,Settings!$B$4*$E39),IF($F39=Settings!$B$11,MAX(2*Settings!$B$12,Settings!$B$4*$E39),""))) | H39: =IF($B39="","",IF(LEFT($F39,6)="Listed","Quantity 0: shown on the station as a reminder, not weighed. Give it a weight to weigh it.",IF(LEFT($F39,7)="NEITHER","Cannot be weighed — split it, premix it, or raise the batch size",IF($G39>Settings!$B$4*$E39+0.0001,"Held to the scale's resolution, not "&TEXT(Settings!$B$4,"0%"),""))))
A40: =IF($B40="","",32) | D40: =IF($B40="","",$C40/1000) | E40: =IF($B40="","",$D40*$C$4) | F40: =IF($B40="","",IF($C40=0,"Listed — not weighed",IF($E40<0,"NEITHER — negative weight",IF($E40>=Settings!$B$19,Settings!$B$6,IF($E40>Settings!$B$14,"NEITHER — over bench capacity",IF($E40>=2*Settings!$B$12,Settings!$B$11,"NEITHER — under bench resolution")))))) | G40: =IF($B40="","",IF($F40=Settings!$B$6,MAX(2*Settings!$B$7,Settings!$B$4*$E40),IF($F40=Settings!$B$11,MAX(2*Settings!$B$12,Settings!$B$4*$E40),""))) | H40: =IF($B40="","",IF(LEFT($F40,6)="Listed","Quantity 0: shown on the station as a reminder, not weighed. Give it a weight to weigh it.",IF(LEFT($F40,7)="NEITHER","Cannot be weighed — split it, premix it, or raise the batch size",IF($G40>Settings!$B$4*$E40+0.0001,"Held to the scale's resolution, not "&TEXT(Settings!$B$4,"0%"),""))))
...

Sheet Teriyaki Jerky
A1: Teriyaki Jerky
A2: Type in the shaded cells only. Weights are GRAMS PER 1 KG OF MEAT. Everything to the right is calculated.
A3: Batch type | C3: Per 1 kg of meat | D3: Quantities scale with the meat weighed at the station.
A4: Batch base weight (g) | C4: 3200 | D4: A typical batch. Only the Target / Weigh-on / Tolerance columns use it — the station recomputes them from the meat it actually weighs.
A5: Product ID | C5: teriyaki_jerky | D5: Bases this applies to | F5: chicken, pork, beef, mutton, fish
A6: Flour ingredient | D6: Water ingredient
A7: Meat | D7: Which animal this product is made from. The operator is not asked — the product implies it. Leave blank if undecided.
A8: # | B8: Ingredient | C8: g per 1 kg meat | D8: % of meat | E8: Target in this batch | F8: Weigh on | G8: Tolerance ± | H8: Note
A9: =IF($B9="","",1) -> 1 | B9: teriyaki sauce | C9: 73 | D9: =IF($B9="","",$C9/1000) -> 0.073 | E9: =IF($B9="","",$D9*$C$4) -> 233.6 | F9: =IF($B9="","",IF($C9=0,"Listed — not weighed",IF($E9<0,"NEITHER — negative weight",IF($E9>=Settings!$B$19,Settings!$B$6,IF($E9>Settings!$B$14,"NEITHER — over bench capacity",IF($E9>=2*Settings!$B$12,Settings!$B$11,"NEITHER — under bench resolution")))))) -> Main scale | G9: =IF($B9="","",IF($F9=Settings!$B$6,MAX(2*Settings!$B$7,Settings!$B$4*$E9),IF($F9=Settings!$B$11,MAX(2*Settings!$B$12,Settings!$B$4*$E9),""))) -> 4.672 | H9: =IF($B9="","",IF(LEFT($F9,6)="Listed","Quantity 0: shown on the station as a reminder, not weighed. Give it a weight to weigh it.",IF(LEFT($F9,7)="NEITHER","Cannot be weighed — split it, premix it, or raise the batch size",IF($G9>Settings!$B$4*$E9+0.0001,"Held to the scale's resolution, not "&TEXT(Settings!$B$4,"0%"),""))))
A10: =IF($B10="","",2) -> 2 | B10: soy sauce | C10: 46.4 | D10: =IF($B10="","",$C10/1000) -> 0.0464 | E10: =IF($B10="","",$D10*$C$4) -> 148.48 | F10: =IF($B10="","",IF($C10=0,"Listed — not weighed",IF($E10<0,"NEITHER — negative weight",IF($E10>=Settings!$B$19,Settings!$B$6,IF($E10>Settings!$B$14,"NEITHER — over bench capacity",IF($E10>=2*Settings!$B$12,Settings!$B$11,"NEITHER — under bench resolution")))))) -> Main scale | G10: =IF($B10="","",IF($F10=Settings!$B$6,MAX(2*Settings!$B$7,Settings!$B$4*$E10),IF($F10=Settings!$B$11,MAX(2*Settings!$B$12,Settings!$B$4*$E10),""))) -> 2.9696 | H10: =IF($B10="","",IF(LEFT($F10,6)="Listed","Quantity 0: shown on the station as a reminder, not weighed. Give it a weight to weigh it.",IF(LEFT($F10,7)="NEITHER","Cannot be weighed — split it, premix it, or raise the batch size",IF($G10>Settings!$B$4*$E10+0.0001,"Held to the scale's resolution, not "&TEXT(Settings!$B$4,"0%"),""))))
A11: =IF($B11="","",3) -> 3 | B11: honey | C11: 42 | D11: =IF($B11="","",$C11/1000) -> 0.042 | E11: =IF($B11="","",$D11*$C$4) -> 134.4 | F11: =IF($B11="","",IF($C11=0,"Listed — not weighed",IF($E11<0,"NEITHER — negative weight",IF($E11>=Settings!$B$19,Settings!$B$6,IF($E11>Settings!$B$14,"NEITHER — over bench capacity",IF($E11>=2*Settings!$B$12,Settings!$B$11,"NEITHER — under bench resolution")))))) -> Main scale | G11: =IF($B11="","",IF($F11=Settings!$B$6,MAX(2*Settings!$B$7,Settings!$B$4*$E11),IF($F11=Settings!$B$11,MAX(2*Settings!$B$12,Settings!$B$4*$E11),""))) -> 2.688 | H11: =IF($B11="","",IF(LEFT($F11,6)="Listed","Quantity 0: shown on the station as a reminder, not weighed. Give it a weight to weigh it.",IF(LEFT($F11,7)="NEITHER","Cannot be weighed — split it, premix it, or raise the batch size",IF($G11>Settings!$B$4*$E11+0.0001,"Held to the scale's resolution, not "&TEXT(Settings!$B$4,"0%"),""))))
A12: =IF($B12="","",4) -> 4 | B12: Tamarind pulp | C12: 25.4 | D12: =IF($B12="","",$C12/1000) -> 0.0254 | E12: =IF($B12="","",$D12*$C$4) -> 81.28 | F12: =IF($B12="","",IF($C12=0,"Listed — not weighed",IF($E12<0,"NEITHER — negative weight",IF($E12>=Settings!$B$19,Settings!$B$6,IF($E12>Settings!$B$14,"NEITHER — over bench capacity",IF($E12>=2*Settings!$B$12,Settings!$B$11,"NEITHER — under bench resolution")))))) -> Main scale | G12: =IF($B12="","",IF($F12=Settings!$B$6,MAX(2*Settings!$B$7,Settings!$B$4*$E12),IF($F12=Settings!$B$11,MAX(2*Settings!$B$12,Settings!$B$4*$E12),""))) -> 2 | H12: =IF($B12="","",IF(LEFT($F12,6)="Listed","Quantity 0: shown on the station as a reminder, not weighed. Give it a weight to weigh it.",IF(LEFT($F12,7)="NEITHER","Cannot be weighed — split it, premix it, or raise the batch size",IF($G12>Settings!$B$4*$E12+0.0001,"Held to the scale's resolution, not "&TEXT(Settings!$B$4,"0%"),"")))) -> Held to the scale's resolution, not 2%
A13: =IF($B13="","",5) -> 5 | B13: White vinegar | C13: 25.4 | D13: =IF($B13="","",$C13/1000) -> 0.0254 | E13: =IF($B13="","",$D13*$C$4) -> 81.28 | F13: =IF($B13="","",IF($C13=0,"Listed — not weighed",IF($E13<0,"NEITHER — negative weight",IF($E13>=Settings!$B$19,Settings!$B$6,IF($E13>Settings!$B$14,"NEITHER — over bench capacity",IF($E13>=2*Settings!$B$12,Settings!$B$11,"NEITHER — under bench resolution")))))) -> Main scale | G13: =IF($B13="","",IF($F13=Settings!$B$6,MAX(2*Settings!$B$7,Settings!$B$4*$E13),IF($F13=Settings!$B$11,MAX(2*Settings!$B$12,Settings!$B$4*$E13),""))) -> 2 | H13: =IF($B13="","",IF(LEFT($F13,6)="Listed","Quantity 0: shown on the station as a reminder, not weighed. Give it a weight to weigh it.",IF(LEFT($F13,7)="NEITHER","Cannot be weighed — split it, premix it, or raise the batch size",IF($G13>Settings!$B$4*$E13+0.0001,"Held to the scale's resolution, not "&TEXT(Settings!$B$4,"0%"),"")))) -> Held to the scale's resolution, not 2%
A14: =IF($B14="","",6) -> 6 | B14: verdad | C14: 2 | D14: =IF($B14="","",$C14/1000) -> 0.002 | E14: =IF($B14="","",$D14*$C$4) -> 6.4 | F14: =IF($B14="","",IF($C14=0,"Listed — not weighed",IF($E14<0,"NEITHER — negative weight",IF($E14>=Settings!$B$19,Settings!$B$6,IF($E14>Settings!$B$14,"NEITHER — over bench capacity",IF($E14>=2*Settings!$B$12,Settings!$B$11,"NEITHER — under bench resolution")))))) -> Main scale | G14: =IF($B14="","",IF($F14=Settings!$B$6,MAX(2*Settings!$B$7,Settings!$B$4*$E14),IF($F14=Settings!$B$11,MAX(2*Settings!$B$12,Settings!$B$4*$E14),""))) -> 2 | H14: =IF($B14="","",IF(LEFT($F14,6)="Listed","Quantity 0: shown on the station as a reminder, not weighed. Give it a weight to weigh it.",IF(LEFT($F14,7)="NEITHER","Cannot be weighed — split it, premix it, or raise the batch size",IF($G14>Settings!$B$4*$E14+0.0001,"Held to the scale's resolution, not "&TEXT(Settings!$B$4,"0%"),"")))) -> Held to the scale's resolution, not 2%
A15: =IF($B15="","",7) -> 7 | B15: jaggery powder | C15: 23.2 | D15: =IF($B15="","",$C15/1000) -> 0.0232 | E15: =IF($B15="","",$D15*$C$4) -> 74.24 | F15: =IF($B15="","",IF($C15=0,"Listed — not weighed",IF($E15<0,"NEITHER — negative weight",IF($E15>=Settings!$B$19,Settings!$B$6,IF($E15>Settings!$B$14,"NEITHER — over bench capacity",IF($E15>=2*Settings!$B$12,Settings!$B$11,"NEITHER — under bench resolution")))))) -> Main scale | G15: =IF($B15="","",IF($F15=Settings!$B$6,MAX(2*Settings!$B$7,Settings!$B$4*$E15),IF($F15=Settings!$B$11,MAX(2*Settings!$B$12,Settings!$B$4*$E15),""))) -> 2 | H15: =IF($B15="","",IF(LEFT($F15,6)="Listed","Quantity 0: shown on the station as a reminder, not weighed. Give it a weight to weigh it.",IF(LEFT($F15,7)="NEITHER","Cannot be weighed — split it, premix it, or raise the batch size",IF($G15>Settings!$B$4*$E15+0.0001,"Held to the scale's resolution, not "&TEXT(Settings!$B$4,"0%"),"")))) -> Held to the scale's resolution, not 2%
A16: =IF($B16="","",8) -> 8 | B16: sea salt | C16: 7.5 | D16: =IF($B16="","",$C16/1000) -> 0.0075 | E16: =IF($B16="","",$D16*$C$4) -> 24 | F16: =IF($B16="","",IF($C16=0,"Listed — not weighed",IF($E16<0,"NEITHER — negative weight",IF($E16>=Settings!$B$19,Settings!$B$6,IF($E16>Settings!$B$14,"NEITHER — over bench capacity",IF($E16>=2*Settings!$B$12,Settings!$B$11,"NEITHER — under bench resolution")))))) -> Main scale | G16: =IF($B16="","",IF($F16=Settings!$B$6,MAX(2*Settings!$B$7,Settings!$B$4*$E16),IF($F16=Settings!$B$11,MAX(2*Settings!$B$12,Settings!$B$4*$E16),""))) -> 2 | H16: =IF($B16="","",IF(LEFT($F16,6)="Listed","Quantity 0: shown on the station as a reminder, not weighed. Give it a weight to weigh it.",IF(LEFT($F16,7)="NEITHER","Cannot be weighed — split it, premix it, or raise the batch size",IF($G16>Settings!$B$4*$E16+0.0001,"Held to the scale's resolution, not "&TEXT(Settings!$B$4,"0%"),"")))) -> Held to the scale's resolution, not 2%
A17: =IF($B17="","",9) -> 9 | B17: seasame seed | C17: 4.5 | D17: =IF($B17="","",$C17/1000) -> 0.0045 | E17: =IF($B17="","",$D17*$C$4) -> 14.4 | F17: =IF($B17="","",IF($C17=0,"Listed — not weighed",IF($E17<0,"NEITHER — negative weight",IF($E17>=Settings!$B$19,Settings!$B$6,IF($E17>Settings!$B$14,"NEITHER — over bench capacity",IF($E17>=2*Settings!$B$12,Settings!$B$11,"NEITHER — under bench resolution")))))) -> Main scale | G17: =IF($B17="","",IF($F17=Settings!$B$6,MAX(2*Settings!$B$7,Settings!$B$4*$E17),IF($F17=Settings!$B$11,MAX(2*Settings!$B$12,Settings!$B$4*$E17),""))) -> 2 | H17: =IF($B17="","",IF(LEFT($F17,6)="Listed","Quantity 0: shown on the station as a reminder, not weighed. Give it a weight to weigh it.",IF(LEFT($F17,7)="NEITHER","Cannot be weighed — split it, premix it, or raise the batch size",IF($G17>Settings!$B$4*$E17+0.0001,"Held to the scale's resolution, not "&TEXT(Settings!$B$4,"0%"),"")))) -> Held to the scale's resolution, not 2%
A18: =IF($B18="","",10) -> 10 | B18: Yeast extract | C18: 1 | D18: =IF($B18="","",$C18/1000) -> 0.001 | E18: =IF($B18="","",$D18*$C$4) -> 3.2 | F18: =IF($B18="","",IF($C18=0,"Listed — not weighed",IF($E18<0,"NEITHER — negative weight",IF($E18>=Settings!$B$19,Settings!$B$6,IF($E18>Settings!$B$14,"NEITHER — over bench capacity",IF($E18>=2*Settings!$B$12,Settings!$B$11,"NEITHER — under bench resolution")))))) -> Small scale | G18: =IF($B18="","",IF($F18=Settings!$B$6,MAX(2*Settings!$B$7,Settings!$B$4*$E18),IF($F18=Settings!$B$11,MAX(2*Settings!$B$12,Settings!$B$4*$E18),""))) -> 0.2 | H18: =IF($B18="","",IF(LEFT($F18,6)="Listed","Quantity 0: shown on the station as a reminder, not weighed. Give it a weight to weigh it.",IF(LEFT($F18,7)="NEITHER","Cannot be weighed — split it, premix it, or raise the batch size",IF($G18>Settings!$B$4*$E18+0.0001,"Held to the scale's resolution, not "&TEXT(Settings!$B$4,"0%"),"")))) -> Held to the scale's resolution, not 2%
A19: =IF($B19="","",11) -> 11 | B19: black pepper | C19: 1.1 | D19: =IF($B19="","",$C19/1000) -> 0.0011 | E19: =IF($B19="","",$D19*$C$4) -> 3.52 | F19: =IF($B19="","",IF($C19=0,"Listed — not weighed",IF($E19<0,"NEITHER — negative weight",IF($E19>=Settings!$B$19,Settings!$B$6,IF($E19>Settings!$B$14,"NEITHER — over bench capacity",IF($E19>=2*Settings!$B$12,Settings!$B$11,"NEITHER — under bench resolution")))))) -> Small scale | G19: =IF($B19="","",IF($F19=Settings!$B$6,MAX(2*Settings!$B$7,Settings!$B$4*$E19),IF($F19=Settings!$B$11,MAX(2*Settings!$B$12,Settings!$B$4*$E19),""))) -> 0.2 | H19: =IF($B19="","",IF(LEFT($F19,6)="Listed","Quantity 0: shown on the station as a reminder, not weighed. Give it a weight to weigh it.",IF(LEFT($F19,7)="NEITHER","Cannot be weighed — split it, premix it, or raise the batch size",IF($G19>Settings!$B$4*$E19+0.0001,"Held to the scale's resolution, not "&TEXT(Settings!$B$4,"0%"),"")))) -> Held to the scale's resolution, not 2%
A20: =IF($B20="","",12) -> 12 | B20: Onion powder | C20: 1.4 | D20: =IF($B20="","",$C20/1000) -> 0.0014 | E20: =IF($B20="","",$D20*$C$4) -> 4.48 | F20: =IF($B20="","",IF($C20=0,"Listed — not weighed",IF($E20<0,"NEITHER — negative weight",IF($E20>=Settings!$B$19,Settings!$B$6,IF($E20>Settings!$B$14,"NEITHER — over bench capacity",IF($E20>=2*Settings!$B$12,Settings!$B$11,"NEITHER — under bench resolution")))))) -> Main scale | G20: =IF($B20="","",IF($F20=Settings!$B$6,MAX(2*Settings!$B$7,Settings!$B$4*$E20),IF($F20=Settings!$B$11,MAX(2*Settings!$B$12,Settings!$B$4*$E20),""))) -> 2 | H20: =IF($B20="","",IF(LEFT($F20,6)="Listed","Quantity 0: shown on the station as a reminder, not weighed. Give it a weight to weigh it.",IF(LEFT($F20,7)="NEITHER","Cannot be weighed — split it, premix it, or raise the batch size",IF($G20>Settings!$B$4*$E20+0.0001,"Held to the scale's resolution, not "&TEXT(Settings!$B$4,"0%"),"")))) -> Held to the scale's resolution, not 2%
A21: =IF($B21="","",13) -> 13 | B21: chilli flake | C21: 1.3 | D21: =IF($B21="","",$C21/1000) -> 0.0013 | E21: =IF($B21="","",$D21*$C$4) -> 4.16 | F21: =IF($B21="","",IF($C21=0,"Listed — not weighed",IF($E21<0,"NEITHER — negative weight",IF($E21>=Settings!$B$19,Settings!$B$6,IF($E21>Settings!$B$14,"NEITHER — over bench capacity",IF($E21>=2*Settings!$B$12,Settings!$B$11,"NEITHER — under bench resolution")))))) -> Main scale | G21: =IF($B21="","",IF($F21=Settings!$B$6,MAX(2*Settings!$B$7,Settings!$B$4*$E21),IF($F21=Settings!$B$11,MAX(2*Settings!$B$12,Settings!$B$4*$E21),""))) -> 2 | H21: =IF($B21="","",IF(LEFT($F21,6)="Listed","Quantity 0: shown on the station as a reminder, not weighed. Give it a weight to weigh it.",IF(LEFT($F21,7)="NEITHER","Cannot be weighed — split it, premix it, or raise the batch size",IF($G21>Settings!$B$4*$E21+0.0001,"Held to the scale's resolution, not "&TEXT(Settings!$B$4,"0%"),"")))) -> Held to the scale's resolution, not 2%
A22: =IF($B22="","",14) -> 14 | B22: garlic powder | C22: 0.6 | D22: =IF($B22="","",$C22/1000) -> 0.0006 | E22: =IF($B22="","",$D22*$C$4) -> 1.92 | F22: =IF($B22="","",IF($C22=0,"Listed — not weighed",IF($E22<0,"NEITHER — negative weight",IF($E22>=Settings!$B$19,Settings!$B$6,IF($E22>Settings!$B$14,"NEITHER — over bench capacity",IF($E22>=2*Settings!$B$12,Settings!$B$11,"NEITHER — under bench resolution")))))) -> Small scale | G22: =IF($B22="","",IF($F22=Settings!$B$6,MAX(2*Settings!$B$7,Settings!$B$4*$E22),IF($F22=Settings!$B$11,MAX(2*Settings!$B$12,Settings!$B$4*$E22),""))) -> 0.2 | H22: =IF($B22="","",IF(LEFT($F22,6)="Listed","Quantity 0: shown on the station as a reminder, not weighed. Give it a weight to weigh it.",IF(LEFT($F22,7)="NEITHER","Cannot be weighed — split it, premix it, or raise the batch size",IF($G22>Settings!$B$4*$E22+0.0001,"Held to the scale's resolution, not "&TEXT(Settings!$B$4,"0%"),"")))) -> Held to the scale's resolution, not 2%
A23: =IF($B23="","",15) -> 15 | B23: bhut jholokia | C23: 0.25 | D23: =IF($B23="","",$C23/1000) -> 0.00025 | E23: =IF($B23="","",$D23*$C$4) -> 0.8 | F23: =IF($B23="","",IF($C23=0,"Listed — not weighed",IF($E23<0,"NEITHER — negative weight",IF($E23>=Settings!$B$19,Settings!$B$6,IF($E23>Settings!$B$14,"NEITHER — over bench capacity",IF($E23>=2*Settings!$B$12,Settings!$B$11,"NEITHER — under bench resolution")))))) -> Small scale | G23: =IF($B23="","",IF($F23=Settings!$B$6,MAX(2*Settings!$B$7,Settings!$B$4*$E23),IF($F23=Settings!$B$11,MAX(2*Settings!$B$12,Settings!$B$4*$E23),""))) -> 0.2 | H23: =IF($B23="","",IF(LEFT($F23,6)="Listed","Quantity 0: shown on the station as a reminder, not weighed. Give it a weight to weigh it.",IF(LEFT($F23,7)="NEITHER","Cannot be weighed — split it, premix it, or raise the batch size",IF($G23>Settings!$B$4*$E23+0.0001,"Held to the scale's resolution, not "&TEXT(Settings!$B$4,"0%"),"")))) -> Held to the scale's resolution, not 2%
A24: =IF($B24="","",16) -> 16 | B24: liquid smoke | C24: 0 | D24: =IF($B24="","",$C24/1000) -> 0 | E24: =IF($B24="","",$D24*$C$4) -> 0 | F24: =IF($B24="","",IF($C24=0,"Listed — not weighed",IF($E24<0,"NEITHER — negative weight",IF($E24>=Settings!$B$19,Settings!$B$6,IF($E24>Settings!$B$14,"NEITHER — over bench capacity",IF($E24>=2*Settings!$B$12,Settings!$B$11,"NEITHER — under bench resolution")))))) -> Listed — not weighed | G24: =IF($B24="","",IF($F24=Settings!$B$6,MAX(2*Settings!$B$7,Settings!$B$4*$E24),IF($F24=Settings!$B$11,MAX(2*Settings!$B$12,Settings!$B$4*$E24),""))) | H24: =IF($B24="","",IF(LEFT($F24,6)="Listed","Quantity 0: shown on the station as a reminder, not weighed. Give it a weight to weigh it.",IF(LEFT($F24,7)="NEITHER","Cannot be weighed — split it, premix it, or raise the batch size",IF($G24>Settings!$B$4*$E24+0.0001,"Held to the scale's resolution, not "&TEXT(Settings!$B$4,"0%"),"")))) -> Quantity 0: shown on the station as a reminder, not weighed. Give it a weight to weigh it.
A25: =IF($B25="","",17) | D25: =IF($B25="","",$C25/1000) | E25: =IF($B25="","",$D25*$C$4) | F25: =IF($B25="","",IF($C25=0,"Listed — not weighed",IF($E25<0,"NEITHER — negative weight",IF($E25>=Settings!$B$19,Settings!$B$6,IF($E25>Settings!$B$14,"NEITHER — over bench capacity",IF($E25>=2*Settings!$B$12,Settings!$B$11,"NEITHER — under bench resolution")))))) | G25: =IF($B25="","",IF($F25=Settings!$B$6,MAX(2*Settings!$B$7,Settings!$B$4*$E25),IF($F25=Settings!$B$11,MAX(2*Settings!$B$12,Settings!$B$4*$E25),""))) | H25: =IF($B25="","",IF(LEFT($F25,6)="Listed","Quantity 0: shown on the station as a reminder, not weighed. Give it a weight to weigh it.",IF(LEFT($F25,7)="NEITHER","Cannot be weighed — split it, premix it, or raise the batch size",IF($G25>Settings!$B$4*$E25+0.0001,"Held to the scale's resolution, not "&TEXT(Settings!$B$4,"0%"),""))))
A26: =IF($B26="","",18) | D26: =IF($B26="","",$C26/1000) | E26: =IF($B26="","",$D26*$C$4) | F26: =IF($B26="","",IF($C26=0,"Listed — not weighed",IF($E26<0,"NEITHER — negative weight",IF($E26>=Settings!$B$19,Settings!$B$6,IF($E26>Settings!$B$14,"NEITHER — over bench capacity",IF($E26>=2*Settings!$B$12,Settings!$B$11,"NEITHER — under bench resolution")))))) | G26: =IF($B26="","",IF($F26=Settings!$B$6,MAX(2*Settings!$B$7,Settings!$B$4*$E26),IF($F26=Settings!$B$11,MAX(2*Settings!$B$12,Settings!$B$4*$E26),""))) | H26: =IF($B26="","",IF(LEFT($F26,6)="Listed","Quantity 0: shown on the station as a reminder, not weighed. Give it a weight to weigh it.",IF(LEFT($F26,7)="NEITHER","Cannot be weighed — split it, premix it, or raise the batch size",IF($G26>Settings!$B$4*$E26+0.0001,"Held to the scale's resolution, not "&TEXT(Settings!$B$4,"0%"),""))))
A27: =IF($B27="","",19) | D27: =IF($B27="","",$C27/1000) | E27: =IF($B27="","",$D27*$C$4) | F27: =IF($B27="","",IF($C27=0,"Listed — not weighed",IF($E27<0,"NEITHER — negative weight",IF($E27>=Settings!$B$19,Settings!$B$6,IF($E27>Settings!$B$14,"NEITHER — over bench capacity",IF($E27>=2*Settings!$B$12,Settings!$B$11,"NEITHER — under bench resolution")))))) | G27: =IF($B27="","",IF($F27=Settings!$B$6,MAX(2*Settings!$B$7,Settings!$B$4*$E27),IF($F27=Settings!$B$11,MAX(2*Settings!$B$12,Settings!$B$4*$E27),""))) | H27: =IF($B27="","",IF(LEFT($F27,6)="Listed","Quantity 0: shown on the station as a reminder, not weighed. Give it a weight to weigh it.",IF(LEFT($F27,7)="NEITHER","Cannot be weighed — split it, premix it, or raise the batch size",IF($G27>Settings!$B$4*$E27+0.0001,"Held to the scale's resolution, not "&TEXT(Settings!$B$4,"0%"),""))))
A28: =IF($B28="","",20) | D28: =IF($B28="","",$C28/1000) | E28: =IF($B28="","",$D28*$C$4) | F28: =IF($B28="","",IF($C28=0,"Listed — not weighed",IF($E28<0,"NEITHER — negative weight",IF($E28>=Settings!$B$19,Settings!$B$6,IF($E28>Settings!$B$14,"NEITHER — over bench capacity",IF($E28>=2*Settings!$B$12,Settings!$B$11,"NEITHER — under bench resolution")))))) | G28: =IF($B28="","",IF($F28=Settings!$B$6,MAX(2*Settings!$B$7,Settings!$B$4*$E28),IF($F28=Settings!$B$11,MAX(2*Settings!$B$12,Settings!$B$4*$E28),""))) | H28: =IF($B28="","",IF(LEFT($F28,6)="Listed","Quantity 0: shown on the station as a reminder, not weighed. Give it a weight to weigh it.",IF(LEFT($F28,7)="NEITHER","Cannot be weighed — split it, premix it, or raise the batch size",IF($G28>Settings!$B$4*$E28+0.0001,"Held to the scale's resolution, not "&TEXT(Settings!$B$4,"0%"),""))))
A29: =IF($B29="","",21) | D29: =IF($B29="","",$C29/1000) | E29: =IF($B29="","",$D29*$C$4) | F29: =IF($B29="","",IF($C29=0,"Listed — not weighed",IF($E29<0,"NEITHER — negative weight",IF($E29>=Settings!$B$19,Settings!$B$6,IF($E29>Settings!$B$14,"NEITHER — over bench capacity",IF($E29>=2*Settings!$B$12,Settings!$B$11,"NEITHER — under bench resolution")))))) | G29: =IF($B29="","",IF($F29=Settings!$B$6,MAX(2*Settings!$B$7,Settings!$B$4*$E29),IF($F29=Settings!$B$11,MAX(2*Settings!$B$12,Settings!$B$4*$E29),""))) | H29: =IF($B29="","",IF(LEFT($F29,6)="Listed","Quantity 0: shown on the station as a reminder, not weighed. Give it a weight to weigh it.",IF(LEFT($F29,7)="NEITHER","Cannot be weighed — split it, premix it, or raise the batch size",IF($G29>Settings!$B$4*$E29+0.0001,"Held to the scale's resolution, not "&TEXT(Settings!$B$4,"0%"),""))))
A30: =IF($B30="","",22) | D30: =IF($B30="","",$C30/1000) | E30: =IF($B30="","",$D30*$C$4) | F30: =IF($B30="","",IF($C30=0,"Listed — not weighed",IF($E30<0,"NEITHER — negative weight",IF($E30>=Settings!$B$19,Settings!$B$6,IF($E30>Settings!$B$14,"NEITHER — over bench capacity",IF($E30>=2*Settings!$B$12,Settings!$B$11,"NEITHER — under bench resolution")))))) | G30: =IF($B30="","",IF($F30=Settings!$B$6,MAX(2*Settings!$B$7,Settings!$B$4*$E30),IF($F30=Settings!$B$11,MAX(2*Settings!$B$12,Settings!$B$4*$E30),""))) | H30: =IF($B30="","",IF(LEFT($F30,6)="Listed","Quantity 0: shown on the station as a reminder, not weighed. Give it a weight to weigh it.",IF(LEFT($F30,7)="NEITHER","Cannot be weighed — split it, premix it, or raise the batch size",IF($G30>Settings!$B$4*$E30+0.0001,"Held to the scale's resolution, not "&TEXT(Settings!$B$4,"0%"),""))))
A31: =IF($B31="","",23) | D31: =IF($B31="","",$C31/1000) | E31: =IF($B31="","",$D31*$C$4) | F31: =IF($B31="","",IF($C31=0,"Listed — not weighed",IF($E31<0,"NEITHER — negative weight",IF($E31>=Settings!$B$19,Settings!$B$6,IF($E31>Settings!$B$14,"NEITHER — over bench capacity",IF($E31>=2*Settings!$B$12,Settings!$B$11,"NEITHER — under bench resolution")))))) | G31: =IF($B31="","",IF($F31=Settings!$B$6,MAX(2*Settings!$B$7,Settings!$B$4*$E31),IF($F31=Settings!$B$11,MAX(2*Settings!$B$12,Settings!$B$4*$E31),""))) | H31: =IF($B31="","",IF(LEFT($F31,6)="Listed","Quantity 0: shown on the station as a reminder, not weighed. Give it a weight to weigh it.",IF(LEFT($F31,7)="NEITHER","Cannot be weighed — split it, premix it, or raise the batch size",IF($G31>Settings!$B$4*$E31+0.0001,"Held to the scale's resolution, not "&TEXT(Settings!$B$4,"0%"),""))))
A32: =IF($B32="","",24) | D32: =IF($B32="","",$C32/1000) | E32: =IF($B32="","",$D32*$C$4) | F32: =IF($B32="","",IF($C32=0,"Listed — not weighed",IF($E32<0,"NEITHER — negative weight",IF($E32>=Settings!$B$19,Settings!$B$6,IF($E32>Settings!$B$14,"NEITHER — over bench capacity",IF($E32>=2*Settings!$B$12,Settings!$B$11,"NEITHER — under bench resolution")))))) | G32: =IF($B32="","",IF($F32=Settings!$B$6,MAX(2*Settings!$B$7,Settings!$B$4*$E32),IF($F32=Settings!$B$11,MAX(2*Settings!$B$12,Settings!$B$4*$E32),""))) | H32: =IF($B32="","",IF(LEFT($F32,6)="Listed","Quantity 0: shown on the station as a reminder, not weighed. Give it a weight to weigh it.",IF(LEFT($F32,7)="NEITHER","Cannot be weighed — split it, premix it, or raise the batch size",IF($G32>Settings!$B$4*$E32+0.0001,"Held to the scale's resolution, not "&TEXT(Settings!$B$4,"0%"),""))))
A33: =IF($B33="","",25) | D33: =IF($B33="","",$C33/1000) | E33: =IF($B33="","",$D33*$C$4) | F33: =IF($B33="","",IF($C33=0,"Listed — not weighed",IF($E33<0,"NEITHER — negative weight",IF($E33>=Settings!$B$19,Settings!$B$6,IF($E33>Settings!$B$14,"NEITHER — over bench capacity",IF($E33>=2*Settings!$B$12,Settings!$B$11,"NEITHER — under bench resolution")))))) | G33: =IF($B33="","",IF($F33=Settings!$B$6,MAX(2*Settings!$B$7,Settings!$B$4*$E33),IF($F33=Settings!$B$11,MAX(2*Settings!$B$12,Settings!$B$4*$E33),""))) | H33: =IF($B33="","",IF(LEFT($F33,6)="Listed","Quantity 0: shown on the station as a reminder, not weighed. Give it a weight to weigh it.",IF(LEFT($F33,7)="NEITHER","Cannot be weighed — split it, premix it, or raise the batch size",IF($G33>Settings!$B$4*$E33+0.0001,"Held to the scale's resolution, not "&TEXT(Settings!$B$4,"0%"),""))))
A34: =IF($B34="","",26) | D34: =IF($B34="","",$C34/1000) | E34: =IF($B34="","",$D34*$C$4) | F34: =IF($B34="","",IF($C34=0,"Listed — not weighed",IF($E34<0,"NEITHER — negative weight",IF($E34>=Settings!$B$19,Settings!$B$6,IF($E34>Settings!$B$14,"NEITHER — over bench capacity",IF($E34>=2*Settings!$B$12,Settings!$B$11,"NEITHER — under bench resolution")))))) | G34: =IF($B34="","",IF($F34=Settings!$B$6,MAX(2*Settings!$B$7,Settings!$B$4*$E34),IF($F34=Settings!$B$11,MAX(2*Settings!$B$12,Settings!$B$4*$E34),""))) | H34: =IF($B34="","",IF(LEFT($F34,6)="Listed","Quantity 0: shown on the station as a reminder, not weighed. Give it a weight to weigh it.",IF(LEFT($F34,7)="NEITHER","Cannot be weighed — split it, premix it, or raise the batch size",IF($G34>Settings!$B$4*$E34+0.0001,"Held to the scale's resolution, not "&TEXT(Settings!$B$4,"0%"),""))))
A35: =IF($B35="","",27) | D35: =IF($B35="","",$C35/1000) | E35: =IF($B35="","",$D35*$C$4) | F35: =IF($B35="","",IF($C35=0,"Listed — not weighed",IF($E35<0,"NEITHER — negative weight",IF($E35>=Settings!$B$19,Settings!$B$6,IF($E35>Settings!$B$14,"NEITHER — over bench capacity",IF($E35>=2*Settings!$B$12,Settings!$B$11,"NEITHER — under bench resolution")))))) | G35: =IF($B35="","",IF($F35=Settings!$B$6,MAX(2*Settings!$B$7,Settings!$B$4*$E35),IF($F35=Settings!$B$11,MAX(2*Settings!$B$12,Settings!$B$4*$E35),""))) | H35: =IF($B35="","",IF(LEFT($F35,6)="Listed","Quantity 0: shown on the station as a reminder, not weighed. Give it a weight to weigh it.",IF(LEFT($F35,7)="NEITHER","Cannot be weighed — split it, premix it, or raise the batch size",IF($G35>Settings!$B$4*$E35+0.0001,"Held to the scale's resolution, not "&TEXT(Settings!$B$4,"0%"),""))))
A36: =IF($B36="","",28) | D36: =IF($B36="","",$C36/1000) | E36: =IF($B36="","",$D36*$C$4) | F36: =IF($B36="","",IF($C36=0,"Listed — not weighed",IF($E36<0,"NEITHER — negative weight",IF($E36>=Settings!$B$19,Settings!$B$6,IF($E36>Settings!$B$14,"NEITHER — over bench capacity",IF($E36>=2*Settings!$B$12,Settings!$B$11,"NEITHER — under bench resolution")))))) | G36: =IF($B36="","",IF($F36=Settings!$B$6,MAX(2*Settings!$B$7,Settings!$B$4*$E36),IF($F36=Settings!$B$11,MAX(2*Settings!$B$12,Settings!$B$4*$E36),""))) | H36: =IF($B36="","",IF(LEFT($F36,6)="Listed","Quantity 0: shown on the station as a reminder, not weighed. Give it a weight to weigh it.",IF(LEFT($F36,7)="NEITHER","Cannot be weighed — split it, premix it, or raise the batch size",IF($G36>Settings!$B$4*$E36+0.0001,"Held to the scale's resolution, not "&TEXT(Settings!$B$4,"0%"),""))))
A37: =IF($B37="","",29) | D37: =IF($B37="","",$C37/1000) | E37: =IF($B37="","",$D37*$C$4) | F37: =IF($B37="","",IF($C37=0,"Listed — not weighed",IF($E37<0,"NEITHER — negative weight",IF($E37>=Settings!$B$19,Settings!$B$6,IF($E37>Settings!$B$14,"NEITHER — over bench capacity",IF($E37>=2*Settings!$B$12,Settings!$B$11,"NEITHER — under bench resolution")))))) | G37: =IF($B37="","",IF($F37=Settings!$B$6,MAX(2*Settings!$B$7,Settings!$B$4*$E37),IF($F37=Settings!$B$11,MAX(2*Settings!$B$12,Settings!$B$4*$E37),""))) | H37: =IF($B37="","",IF(LEFT($F37,6)="Listed","Quantity 0: shown on the station as a reminder, not weighed. Give it a weight to weigh it.",IF(LEFT($F37,7)="NEITHER","Cannot be weighed — split it, premix it, or raise the batch size",IF($G37>Settings!$B$4*$E37+0.0001,"Held to the scale's resolution, not "&TEXT(Settings!$B$4,"0%"),""))))
A38: =IF($B38="","",30) | D38: =IF($B38="","",$C38/1000) | E38: =IF($B38="","",$D38*$C$4) | F38: =IF($B38="","",IF($C38=0,"Listed — not weighed",IF($E38<0,"NEITHER — negative weight",IF($E38>=Settings!$B$19,Settings!$B$6,IF($E38>Settings!$B$14,"NEITHER — over bench capacity",IF($E38>=2*Settings!$B$12,Settings!$B$11,"NEITHER — under bench resolution")))))) | G38: =IF($B38="","",IF($F38=Settings!$B$6,MAX(2*Settings!$B$7,Settings!$B$4*$E38),IF($F38=Settings!$B$11,MAX(2*Settings!$B$12,Settings!$B$4*$E38),""))) | H38: =IF($B38="","",IF(LEFT($F38,6)="Listed","Quantity 0: shown on the station as a reminder, not weighed. Give it a weight to weigh it.",IF(LEFT($F38,7)="NEITHER","Cannot be weighed — split it, premix it, or raise the batch size",IF($G38>Settings!$B$4*$E38+0.0001,"Held to the scale's resolution, not "&TEXT(Settings!$B$4,"0%"),""))))
